"""End-to-end integrated tests of default cache"""

import inspect
import os
import subprocess
import sys
import warnings

import pytest
import trio

from .. import _impl
from _trio_parallel_workers._funcs import _block_worker, _raise_pid
from .._impl import (
    get_default_context,
    run_sync,
    open_worker_context,
    default_context_statistics,
    configure_default_context,
)

if sys.platform == "win32":

    @pytest.fixture
    def shutdown_cache():
        configure_default_context()

else:

    @pytest.fixture
    def shutdown_cache():
        yield
        _impl.DEFAULT_CONTEXT._worker_cache.shutdown(50)
        configure_default_context()


async def test_run_sync(shutdown_cache):
    trio_pid = os.getpid()
    limiter = trio.CapacityLimiter(1)

    child_pid = await run_sync(os.getpid, limiter=limiter)
    assert child_pid != trio_pid

    with pytest.raises(ValueError) as excinfo:
        await run_sync(_raise_pid, limiter=limiter)

    assert excinfo.value.args[0] != trio_pid


async def test_entry_cancellation(manager, shutdown_cache):
    async def child(cancellable):
        nonlocal child_start, child_done
        child_start = True
        try:
            return await run_sync(
                _block_worker, block, worker_start, worker_done, cancellable=cancellable
            )
        finally:
            child_done = True

    block, worker_start, worker_done = manager.Event(), manager.Event(), manager.Event()
    child_start = False
    child_done = False

    # If we cancel *before* it enters, the entry is itself a cancellation
    # point
    with trio.CancelScope() as scope:
        scope.cancel()
        await child(False)
    assert scope.cancelled_caught
    assert child_start
    assert child_done
    assert not worker_start.is_set()
    assert not worker_done.is_set()


async def test_kill_cancellation(manager, shutdown_cache):
    async def child(cancellable):
        nonlocal child_start, child_done
        child_start = True
        try:
            return await run_sync(
                _block_worker, block, worker_start, worker_done, cancellable=cancellable
            )
        finally:
            child_done = True

    block, worker_start, worker_done = manager.Event(), manager.Event(), manager.Event()
    child_start = False
    child_done = False
    # prime worker cache so fail timeout doesn't have to be so long
    await run_sync(bool)
    # This is truly cancellable by killing the worker
    async with trio.open_nursery() as nursery:
        nursery.start_soon(child, True)
        # Give it a chance to get started. (This is important because
        # to_thread_run_sync does a checkpoint_if_cancelled before
        # blocking on the thread, and we don't want to trigger this.)
        await trio.testing.wait_all_tasks_blocked(0.01)
        assert child_start
        with trio.fail_after(1):
            await trio.to_thread.run_sync(worker_start.wait, abandon_on_cancel=True)
        # Then cancel it.
        nursery.cancel_scope.cancel()
    # The task exited, but the worker died
    assert not block.is_set()
    assert not worker_done.is_set()
    assert child_done


async def test_uncancellable_cancellation(manager, shutdown_cache):
    async def child(cancellable):
        nonlocal child_start, child_done
        child_start = True
        await run_sync(
            _block_worker, block, worker_start, worker_done, cancellable=cancellable
        )
        child_done = True

    block, worker_start, worker_done = manager.Event(), manager.Event(), manager.Event()
    child_start = False
    child_done = False
    # This one can't be cancelled
    async with trio.open_nursery() as nursery:
        nursery.start_soon(child, False)
        await trio.to_thread.run_sync(worker_start.wait, abandon_on_cancel=True)
        assert child_start
        nursery.cancel_scope.cancel()
        with trio.CancelScope(shield=True):
            await trio.testing.wait_all_tasks_blocked(0.01)
        # It's still running
        assert not worker_done.is_set()
        block.set()
        # Now it exits
    assert child_done
    assert worker_done.is_set()


async def test_aclose():
    async with open_worker_context() as ctx:
        await ctx.run_sync(bool)
    with pytest.raises(trio.ClosedResourceError):
        await ctx.run_sync(bool)


async def test_context_waits(manager):
    # TODO: convert this to a collaboration test
    finished = False
    block = manager.Event()
    start = manager.Event()
    done = manager.Event()

    async def child():
        nonlocal finished
        try:
            await ctx.run_sync(_block_worker, block, start, done)
        finally:
            finished = True

    async with trio.open_nursery() as nursery:
        async with open_worker_context() as ctx:
            nursery.start_soon(child)
            nursery.start_soon(child)
            await trio.to_thread.run_sync(start.wait, abandon_on_cancel=True)
            block.set()
        assert finished


def _atexit_shutdown():  # pragma: no cover, source code extracted
    # run in a subprocess, no access to globals
    import trio

    # note the order here: if trio_parallel is imported after multiprocessing,
    # specifically after invoking the logger, a more naive installation of the atexit
    # handler could be done and still pass the test
    import trio_parallel
    import multiprocessing  # noqa: F811

    # we inspect the logger output in stderr to validate the test
    multiprocessing.log_to_stderr(10)
    trio.run(trio_parallel.run_sync, bool)


def test_we_control_atexit_shutdowns():
    # multiprocessing will either terminate or workers or lock up during its atexit.
    # Our graceful shutdown code allows atexit handlers *in the workers* to run as
    # well as avoiding being joined by the multiprocessing code. We test the latter.
    test_code = f"""{inspect.getsource(_atexit_shutdown)}\nif __name__ == '__main__':
        {_atexit_shutdown.__name__}()"""
    result = subprocess.run(
        [sys.executable, "-c", test_code],
        stderr=subprocess.PIPE,
        check=True,
        timeout=20,
    )
    assert b"[INFO/MainProcess] process shutting down" in result.stderr
    assert b"calling join() for" not in result.stderr


def test_startup_failure_doesnt_hang(tmp_path):
    # Failing to guard startup against worker spawn recursion is the only failure
    # case of startup that I have run into.
    script_path = tmp_path / "script.py"
    with script_path.open("w") as f:
        f.write(
            "import trio,trio_parallel; trio.run(trio_parallel.run_sync, int)\n",
        )
    result = subprocess.run(
        # note str used because cpython subprocess added the feature
        # to understand path-like objects in version 3.8
        [sys.executable, str(script_path)],
        stdout=subprocess.PIPE,
        stderr=subprocess.PIPE,
        check=False,  # we expect a failure
        timeout=20,
    )
    assert not result.stdout
    assert b"An attempt has been made to start a new process" in result.stderr
    assert result.returncode


async def _compare_pids():
    first = await run_sync(os.getpid)
    second = await run_sync(os.getpid)
    return first == second


async def test_configure_default_context(shutdown_cache):
    configure_default_context(retire=object)
    assert not await _compare_pids()


async def test_configure_default_context_warns(shutdown_cache):
    try:
        configure_default_context(idle_timeout=float("inf"))
        assert await _compare_pids()
    finally:
        with pytest.warns(UserWarning):
            warnings.simplefilter("always")
            configure_default_context()


async def test_configure_default_context_thread(shutdown_cache):
    with pytest.raises(RuntimeError, match="thread"):
        await trio.to_thread.run_sync(configure_default_context)


async def test_get_default_context_stats():  # noqa: TRIO910
    s = default_context_statistics()
    assert hasattr(s, "idle_workers")
    assert hasattr(s, "running_workers")
    assert s == get_default_context().statistics()


@pytest.mark.xfail(
    sys.platform == "win32",
    reason="Default cache is not global on Windows",
    raises=AssertionError,
)
def test_sequential_runs(shutdown_cache):
    async def run_with_timeout():
        with trio.fail_after(20):
            return await run_sync(os.getpid, cancellable=True)

    same_pid = trio.run(run_with_timeout) == trio.run(run_with_timeout)
    assert same_pid


async def test_concurrent_runs(shutdown_cache):
    async def worker(i):
        with trio.fail_after(20):
            assert await run_sync(int, i, cancellable=True) == i
            for _ in range(30):
                assert await run_sync(int, i, cancellable=True) == i
            with trio.move_on_after(0.5):
                while True:
                    assert await run_sync(int, i, cancellable=True) == i

    async with trio.open_nursery() as n:
        for i in range(2):
            n.start_soon(trio.to_thread.run_sync, trio.run, worker, i)


def test_nice_names():
    import trio_parallel

    for objname, obj in trio_parallel.__dict__.items():
        if not objname.startswith("_"):  # ignore private attributes
            assert "._" not in obj.__module__
